Workbook

Sheet Dashboard
A1: Payment Cycle Dashboard
A2: All figures calculated live from Invoice Ledger
A4: Metric | B4: Value
A5: Total Invoices | B5: =COUNTA('Invoice Ledger'!A2:A421) -> 420
A6: Total Billed ($) | B6: =SUM('Invoice Ledger'!F2:F421) -> 2211832.8
A7: Open AR Balance ($) | B7: =SUMIFS('Invoice Ledger'!F2:F421,'Invoice Ledger'!H2:H421,"Open") -> 243261.67
A8: Avg Days to Pay | B8: =AVERAGEIFS('Invoice Ledger'!I2:I421,'Invoice Ledger'!H2:H421,"Paid") -> 39.233871
A9: % Paid On Time | B9: =COUNTIFS('Invoice Ledger'!H2:H421,"Paid",'Invoice Ledger'!J2:J421,"<=0")/COUNTIFS('Invoice Ledger'!H2:H421,"Paid") -> 0.50268817
A10: % Open AR 90+ Days | B10: ='Aging Analysis'!C8 -> 0
A12: Note: DSO target = 45 days. See README for methodology.

Sheet Invoice Ledger
A1: Invoice ID | B1: Customer | C1: Issue Date | D1: Due Date | E1: Terms (days) | F1: Amount ($) | G1: Paid Date | H1: Status | I1: Days to Pay | J1: Days Past Due | K1: Aging Bucket
A2: INV-1000 | B2: Customer 001 | C2: 2025-09-22 | D2: 2025-11-06 | E2: 45 | F2: 4230.16 | G2: 2025-11-20 | H2: =IF(G2="","Open","Paid") -> Paid | I2: =IF(G2="","",DATEVALUE(G2)-DATEVALUE(C2)) -> 59 | J2: =IF(G2="",TODAY()-DATEVALUE(D2),DATEVALUE(G2)-DATEVALUE(D2)) -> 14 | K2: =IF(J2<=0,"Current",IF(J2<=30,"1-30 days",IF(J2<=60,"31-60 days",IF(J2<=90,"61-90 days","90+ days")))) -> 1-30 days
A3: INV-1001 | B3: Customer 037 | C3: 2026-01-22 | D3: 2026-02-21 | E3: 30 | F3: 5582.36 | G3: 2026-02-12 | H3: =IF(G3="","Open","Paid") -> Paid | I3: =IF(G3="","",DATEVALUE(G3)-DATEVALUE(C3)) -> 21 | J3: =IF(G3="",TODAY()-DATEVALUE(D3),DATEVALUE(G3)-DATEVALUE(D3)) -> -9 | K3: =IF(J3<=0,"Current",IF(J3<=30,"1-30 days",IF(J3<=60,"31-60 days",IF(J3<=90,"61-90 days","90+ days")))) -> Current
A4: INV-1002 | B4: Customer 039 | C4: 2025-08-22 | D4: 2025-09-21 | E4: 30 | F4: 3180.44 | G4: 2025-09-23 | H4: =IF(G4="","Open","Paid") -> Paid | I4: =IF(G4="","",DATEVALUE(G4)-DATEVALUE(C4)) -> 32 | J4: =IF(G4="",TODAY()-DATEVALUE(D4),DATEVALUE(G4)-DATEVALUE(D4)) -> 2 | K4: =IF(J4<=0,"Current",IF(J4<=30,"1-30 days",IF(J4<=60,"31-60 days",IF(J4<=90,"61-90 days","90+ days")))) -> 1-30 days
A5: INV-1003 | B5: Customer 023 | C5: 2025-10-20 | D5: 2025-11-19 | E5: 30 | F5: 3712.69 | G5: 2025-11-19 | H5: =IF(G5="","Open","Paid") -> Paid | I5: =IF(G5="","",DATEVALUE(G5)-DATEVALUE(C5)) -> 30 | J5: =IF(G5="",TODAY()-DATEVALUE(D5),DATEVALUE(G5)-DATEVALUE(D5)) -> 0 | K5: =IF(J5<=0,"Current",IF(J5<=30,"1-30 days",IF(J5<=60,"31-60 days",IF(J5<=90,"61-90 days","90+ days")))) -> Current
A6: INV-1004 | B6: Customer 029 | C6: 2026-05-27 | D6: 2026-07-11 | E6: 45 | F6: 5648.67 | H6: =IF(G6="","Open","Paid") -> Open | I6: =IF(G6="","",DATEVALUE(G6)-DATEVALUE(C6)) | J6: =IF(G6="",TODAY()-DATEVALUE(D6),DATEVALUE(G6)-DATEVALUE(D6)) -> -8 | K6: =IF(J6<=0,"Current",IF(J6<=30,"1-30 days",IF(J6<=60,"31-60 days",IF(J6<=90,"61-90 days","90+ days")))) -> Current
A7: INV-1005 | B7: Customer 048 | C7: 2025-07-10 | D7: 2025-08-24 | E7: 45 | F7: 3519.85 | G7: 2025-08-15 | H7: =IF(G7="","Open","Paid") -> Paid | I7: =IF(G7="","",DATEVALUE(G7)-DATEVALUE(C7)) -> 36 | J7: =IF(G7="",TODAY()-DATEVALUE(D7),DATEVALUE(G7)-DATEVALUE(D7)) -> -9 | K7: =IF(J7<=0,"Current",IF(J7<=30,"1-30 days",IF(J7<=60,"31-60 days",IF(J7<=90,"61-90 days","90+ days")))) -> Current
A8: INV-1006 | B8: Customer 023 | C8: 2025-09-26 | D8: 2025-10-26 | E8: 30 | F8: 2130.39 | G8: 2025-10-24 | H8: =IF(G8="","Open","Paid") -> Paid | I8: =IF(G8="","",DATEVALUE(G8)-DATEVALUE(C8)) -> 28 | J8: =IF(G8="",TODAY()-DATEVALUE(D8),DATEVALUE(G8)-DATEVALUE(D8)) -> -2 | K8: =IF(J8<=0,"Current",IF(J8<=30,"1-30 days",IF(J8<=60,"31-60 days",IF(J8<=90,"61-90 days","90+ days")))) -> Current
A9: INV-1007 | B9: Customer 004 | C9: 2025-09-17 | D9: 2025-11-01 | E9: 45 | F9: 1143.71 | G9: 2025-10-12 | H9: =IF(G9="","Open","Paid") -> Paid | I9: =IF(G9="","",DATEVALUE(G9)-DATEVALUE(C9)) -> 25 | J9: =IF(G9="",TODAY()-DATEVALUE(D9),DATEVALUE(G9)-DATEVALUE(D9)) -> -20 | K9: =IF(J9<=0,"Current",IF(J9<=30,"1-30 days",IF(J9<=60,"31-60 days",IF(J9<=90,"61-90 days","90+ days")))) -> Current
A10: INV-1008 | B10: Customer 023 | C10: 2026-05-15 | D10: 2026-06-14 | E10: 30 | F10: 4891.45 | G10: 2026-06-15 | H10: =IF(G10="","Open","Paid") -> Paid | I10: =IF(G10="","",DATEVALUE(G10)-DATEVALUE(C10)) -> 31 | J10: =IF(G10="",TODAY()-DATEVALUE(D10),DATEVALUE(G10)-DATEVALUE(D10)) -> 1 | K10: =IF(J10<=0,"Current",IF(J10<=30,"1-30 days",IF(J10<=60,"31-60 days",IF(J10<=90,"61-90 days","90+ days")))) -> 1-30 days
A11: INV-1009 | B11: Customer 016 | C11: 2026-01-18 | D11: 2026-03-04 | E11: 45 | F11: 9326.61 | G11: 2026-03-09 | H11: =IF(G11="","Open","Paid") -> Paid | I11: =IF(G11="","",DATEVALUE(G11)-DATEVALUE(C11)) -> 50 | J11: =IF(G11="",TODAY()-DATEVALUE(D11),DATEVALUE(G11)-DATEVALUE(D11)) -> 5 | K11: =IF(J11<=0,"Current",IF(J11<=30,"1-30 days",IF(J11<=60,"31-60 days",IF(J11<=90,"61-90 days","90+ days")))) -> 1-30 days
A12: INV-1010 | B12: Customer 023 | C12: 2026-02-16 | D12: 2026-04-17 | E12: 60 | F12: 6060.4 | G12: 2026-04-14 | H12: =IF(G12="","Open","Paid") -> Paid | I12: =IF(G12="","",DATEVALUE(G12)-DATEVALUE(C12)) -> 57 | J12: =IF(G12="",TODAY()-DATEVALUE(D12),DATEVALUE(G12)-DATEVALUE(D12)) -> -3 | K12: =IF(J12<=0,"Current",IF(J12<=30,"1-30 days",IF(J12<=60,"31-60 days",IF(J12<=90,"61-90 days","90+ days")))) -> Current
A13: INV-1011 | B13: Customer 014 | C13: 2025-07-28 | D13: 2025-09-11 | E13: 45 | F13: 2189.59 | G13: 2025-08-22 | H13: =IF(G13="","Open","Paid") -> Paid | I13: =IF(G13="","",DATEVALUE(G13)-DATEVALUE(C13)) -> 25 | J13: =IF(G13="",TODAY()-DATEVALUE(D13),DATEVALUE(G13)-DATEVALUE(D13)) -> -20 | K13: =IF(J13<=0,"Current",IF(J13<=30,"1-30 days",IF(J13<=60,"31-60 days",IF(J13<=90,"61-90 days","90+ days")))) -> Current
A14: INV-1012 | B14: Customer 009 | C14: 2025-11-08 | D14: 2025-12-23 | E14: 45 | F14: 2909.64 | G14: 2026-01-03 | H14: =IF(G14="","Open","Paid") -> Paid | I14: =IF(G14="","",DATEVALUE(G14)-DATEVALUE(C14)) -> 56 | J14: =IF(G14="",TODAY()-DATEVALUE(D14),DATEVALUE(G14)-DATEVALUE(D14)) -> 11 | K14: =IF(J14<=0,"Current",IF(J14<=30,"1-30 days",IF(J14<=60,"31-60 days",IF(J14<=90,"61-90 days","90+ days")))) -> 1-30 days
A15: INV-1013 | B15: Customer 060 | C15: 2025-09-04 | D15: 2025-10-19 | E15: 45 | F15: 3903.44 | G15: 2025-10-23 | H15: =IF(G15="","Open","Paid") -> Paid | I15: =IF(G15="","",DATEVALUE(G15)-DATEVALUE(C15)) -> 49 | J15: =IF(G15="",TODAY()-DATEVALUE(D15),DATEVALUE(G15)-DATEVALUE(D15)) -> 4 | K15: =IF(J15<=0,"Current",IF(J15<=30,"1-30 days",IF(J15<=60,"31-60 days",IF(J15<=90,"61-90 days","90+ days")))) -> 1-30 days
A16: INV-1014 | B16: Customer 008 | C16: 2026-01-20 | D16: 2026-02-19 | E16: 30 | F16: 12479.62 | G16: 2026-03-28 | H16: =IF(G16="","Open","Paid") -> Paid | I16: =IF(G16="","",DATEVALUE(G16)-DATEVALUE(C16)) -> 67 | J16: =IF(G16="",TODAY()-DATEVALUE(D16),DATEVALUE(G16)-DATEVALUE(D16)) -> 37 | K16: =IF(J16<=0,"Current",IF(J16<=30,"1-30 days",IF(J16<=60,"31-60 days",IF(J16<=90,"61-90 days","90+ days")))) -> 31-60 days
A17: INV-1015 | B17: Customer 043 | C17: 2026-04-09 | D17: 2026-05-09 | E17: 30 | F17: 12859.52 | G17: 2026-05-05 | H17: =IF(G17="","Open","Paid") -> Paid | I17: =IF(G17="","",DATEVALUE(G17)-DATEVALUE(C17)) -> 26 | J17: =IF(G17="",TODAY()-DATEVALUE(D17),DATEVALUE(G17)-DATEVALUE(D17)) -> -4 | K17: =IF(J17<=0,"Current",IF(J17<=30,"1-30 days",IF(J17<=60,"31-60 days",IF(J17<=90,"61-90 days","90+ days")))) -> Current
A18: INV-1016 | B18: Customer 044 | C18: 2025-12-11 | D18: 2026-01-10 | E18: 30 | F18: 12020.22 | G18: 2025-12-22 | H18: =IF(G18="","Open","Paid") -> Paid | I18: =IF(G18="","",DATEVALUE(G18)-DATEVALUE(C18)) -> 11 | J18: =IF(G18="",TODAY()-DATEVALUE(D18),DATEVALUE(G18)-DATEVALUE(D18)) -> -19 | K18: =IF(J18<=0,"Current",IF(J18<=30,"1-30 days",IF(J18<=60,"31-60 days",IF(J18<=90,"61-90 days","90+ days")))) -> Current
A19: INV-1017 | B19: Customer 038 | C19: 2026-06-07 | D19: 2026-07-07 | E19: 30 | F19: 5195.63 | H19: =IF(G19="","Open","Paid") -> Open | I19: =IF(G19="","",DATEVALUE(G19)-DATEVALUE(C19)) | J19: =IF(G19="",TODAY()-DATEVALUE(D19),DATEVALUE(G19)-DATEVALUE(D19)) -> -4 | K19: =IF(J19<=0,"Current",IF(J19<=30,"1-30 days",IF(J19<=60,"31-60 days",IF(J19<=90,"61-90 days","90+ days")))) -> Current
A20: INV-1018 | B20: Customer 055 | C20: 2025-09-02 | D20: 2025-10-17 | E20: 45 | F20: 21518.35 | G20: 2025-10-10 | H20: =IF(G20="","Open","Paid") -> Paid | I20: =IF(G20="","",DATEVALUE(G20)-DATEVALUE(C20)) -> 38 | J20: =IF(G20="",TODAY()-DATEVALUE(D20),DATEVALUE(G20)-DATEVALUE(D20)) -> -7 | K20: =IF(J20<=0,"Current",IF(J20<=30,"1-30 days",IF(J20<=60,"31-60 days",IF(J20<=90,"61-90 days","90+ days")))) -> Current
A21: INV-1019 | B21: Customer 001 | C21: 2025-11-13 | D21: 2025-12-28 | E21: 45 | F21: 3006.77 | G21: 2026-02-12 | H21: =IF(G21="","Open","Paid") -> Paid | I21: =IF(G21="","",DATEVALUE(G21)-DATEVALUE(C21)) -> 91 | J21: =IF(G21="",TODAY()-DATEVALUE(D21),DATEVALUE(G21)-DATEVALUE(D21)) -> 46 | K21: =IF(J21<=0,"Current",IF(J21<=30,"1-30 days",IF(J21<=60,"31-60 days",IF(J21<=90,"61-90 days","90+ days")))) -> 31-60 days
A22: INV-1020 | B22: Customer 019 | C22: 2025-09-28 | D22: 2025-11-12 | E22: 45 | F22: 3813.05 | G22: 2025-11-04 | H22: =IF(G22="","Open","Paid") -> Paid | I22: =IF(G22="","",DATEVALUE(G22)-DATEVALUE(C22)) -> 37 | J22: =IF(G22="",TODAY()-DATEVALUE(D22),DATEVALUE(G22)-DATEVALUE(D22)) -> -8 | K22: =IF(J22<=0,"Current",IF(J22<=30,"1-30 days",IF(J22<=60,"31-60 days",IF(J22<=90,"61-90 days","90+ days")))) -> Current
A23: INV-1021 | B23: Customer 012 | C23: 2026-02-21 | D23: 2026-03-23 | E23: 30 | F23: 7996.69 | G23: 2026-03-30 | H23: =IF(G23="","Open","Paid") -> Paid | I23: =IF(G23="","",DATEVALUE(G23)-DATEVALUE(C23)) -> 37 | J23: =IF(G23="",TODAY()-DATEVALUE(D23),DATEVALUE(G23)-DATEVALUE(D23)) -> 7 | K23: =IF(J23<=0,"Current",IF(J23<=30,"1-30 days",IF(J23<=60,"31-60 days",IF(J23<=90,"61-90 days","90+ days")))) -> 1-30 days
A24: INV-1022 | B24: Customer 035 | C24: 2025-07-12 | D24: 2025-08-26 | E24: 45 | F24: 5666.29 | G24: 2025-08-19 | H24: =IF(G24="","Open","Paid") -> Paid | I24: =IF(G24="","",DATEVALUE(G24)-DATEVALUE(C24)) -> 38 | J24: =IF(G24="",TODAY()-DATEVALUE(D24),DATEVALUE(G24)-DATEVALUE(D24)) -> -7 | K24: =IF(J24<=0,"Current",IF(J24<=30,"1-30 days",IF(J24<=60,"31-60 days",IF(J24<=90,"61-90 days","90+ days")))) -> Current
A25: INV-1023 | B25: Customer 039 | C25: 2025-08-09 | D25: 2025-09-08 | E25: 30 | F25: 5858.88 | G25: 2025-09-10 | H25: =IF(G25="","Open","Paid") -> Paid | I25: =IF(G25="","",DATEVALUE(G25)-DATEVALUE(C25)) -> 32 | J25: =IF(G25="",TODAY()-DATEVALUE(D25),DATEVALUE(G25)-DATEVALUE(D25)) -> 2 | K25: =IF(J25<=0,"Current",IF(J25<=30,"1-30 days",IF(J25<=60,"31-60 days",IF(J25<=90,"61-90 days","90+ days")))) -> 1-30 days
A26: INV-1024 | B26: Customer 054 | C26: 2025-09-20 | D26: 2025-10-20 | E26: 30 | F26: 2453.42 | G26: 2025-12-05 | H26: =IF(G26="","Open","Paid") -> Paid | I26: =IF(G26="","",DATEVALUE(G26)-DATEVALUE(C26)) -> 76 | J26: =IF(G26="",TODAY()-DATEVALUE(D26),DATEVALUE(G26)-DATEVALUE(D26)) -> 46 | K26: =IF(J26<=0,"Current",IF(J26<=30,"1-30 days",IF(J26<=60,"31-60 days",IF(J26<=90,"61-90 days","90+ days")))) -> 31-60 days
A27: INV-1025 | B27: Customer 023 | C27: 2026-04-21 | D27: 2026-06-05 | E27: 45 | F27: 4630.35 | G27: 2026-06-15 | H27: =IF(G27="","Open","Paid") -> Paid | I27: =IF(G27="","",DATEVALUE(G27)-DATEVALUE(C27)) -> 55 | J27: =IF(G27="",TODAY()-DATEVALUE(D27),DATEVALUE(G27)-DATEVALUE(D27)) -> 10 | K27: =IF(J27<=0,"Current",IF(J27<=30,"1-30 days",IF(J27<=60,"31-60 days",IF(J27<=90,"61-90 days","90+ days")))) -> 1-30 days
A28: INV-1026 | B28: Customer 015 | C28: 2026-01-12 | D28: 2026-03-13 | E28: 60 | F28: 3036.47 | G28: 2026-03-06 | H28: =IF(G28="","Open","Paid") -> Paid | I28: =IF(G28="","",DATEVALUE(G28)-DATEVALUE(C28)) -> 53 | J28: =IF(G28="",TODAY()-DATEVALUE(D28),DATEVALUE(G28)-DATEVALUE(D28)) -> -7 | K28: =IF(J28<=0,"Current",IF(J28<=30,"1-30 days",IF(J28<=60,"31-60 days",IF(J28<=90,"61-90 days","90+ days")))) -> Current
A29: INV-1027 | B29: Customer 056 | C29: 2026-06-15 | D29: 2026-07-30 | E29: 45 | F29: 1836.98 | H29: =IF(G29="","Open","Paid") -> Open | I29: =IF(G29="","",DATEVALUE(G29)-DATEVALUE(C29)) | J29: =IF(G29="",TODAY()-DATEVALUE(D29),DATEVALUE(G29)-DATEVALUE(D29)) -> -27 | K29: =IF(J29<=0,"Current",IF(J29<=30,"1-30 days",IF(J29<=60,"31-60 days",IF(J29<=90,"61-90 days","90+ days")))) -> Current
A30: INV-1028 | B30: Customer 041 | C30: 2026-05-05 | D30: 2026-06-04 | E30: 30 | F30: 3277.91 | G30: 2026-05-18 | H30: =IF(G30="","Open","Paid") -> Paid | I30: =IF(G30="","",DATEVALUE(G30)-DATEVALUE(C30)) -> 13 | J30: =IF(G30="",TODAY()-DATEVALUE(D30),DATEVALUE(G30)-DATEVALUE(D30)) -> -17 | K30: =IF(J30<=0,"Current",IF(J30<=30,"1-30 days",IF(J30<=60,"31-60 days",IF(J30<=90,"61-90 days","90+ days")))) -> Current
A31: INV-1029 | B31: Customer 046 | C31: 2025-10-25 | D31: 2025-12-09 | E31: 45 | F31: 5667.23 | G31: 2025-12-02 | H31: =IF(G31="","Open","Paid") -> Paid | I31: =IF(G31="","",DATEVALUE(G31)-DATEVALUE(C31)) -> 38 | J31: =IF(G31="",TODAY()-DATEVALUE(D31),DATEVALUE(G31)-DATEVALUE(D31)) -> -7 | K31: =IF(J31<=0,"Current",IF(J31<=30,"1-30 days",IF(J31<=60,"31-60 days",IF(J31<=90,"61-90 days","90+ days")))) -> Current
A32: INV-1030 | B32: Customer 027 | C32: 2025-10-02 | D32: 2025-11-01 | E32: 30 | F32: 7259.21 | G32: 2025-10-17 | H32: =IF(G32="","Open","Paid") -> Paid | I32: =IF(G32="","",DATEVALUE(G32)-DATEVALUE(C32)) -> 15 | J32: =IF(G32="",TODAY()-DATEVALUE(D32),DATEVALUE(G32)-DATEVALUE(D32)) -> -15 | K32: =IF(J32<=0,"Current",IF(J32<=30,"1-30 days",IF(J32<=60,"31-60 days",IF(J32<=90,"61-90 days","90+ days")))) -> Current
A33: INV-1031 | B33: Customer 027 | C33: 2025-07-13 | D33: 2025-08-27 | E33: 45 | F33: 1110.04 | G33: 2025-08-31 | H33: =IF(G33="","Open","Paid") -> Paid | I33: =IF(G33="","",DATEVALUE(G33)-DATEVALUE(C33)) -> 49 | J33: =IF(G33="",TODAY()-DATEVALUE(D33),DATEVALUE(G33)-DATEVALUE(D33)) -> 4 | K33: =IF(J33<=0,"Current",IF(J33<=30,"1-30 days",IF(J33<=60,"31-60 days",IF(J33<=90,"61-90 days","90+ days")))) -> 1-30 days
A34: INV-1032 | B34: Customer 024 | C34: 2026-03-04 | D34: 2026-04-18 | E34: 45 | F34: 4763.88 | G34: 2026-04-12 | H34: =IF(G34="","Open","Paid") -> Paid | I34: =IF(G34="","",DATEVALUE(G34)-DATEVALUE(C34)) -> 39 | J34: =IF(G34="",TODAY()-DATEVALUE(D34),DATEVALUE(G34)-DATEVALUE(D34)) -> -6 | K34: =IF(J34<=0,"Current",IF(J34<=30,"1-30 days",IF(J34<=60,"31-60 days",IF(J34<=90,"61-90 days","90+ days")))) -> Current
A35: INV-1033 | B35: Customer 045 | C35: 2026-02-16 | D35: 2026-03-18 | E35: 30 | F35: 4502.38 | G35: 2026-04-15 | H35: =IF(G35="","Open","Paid") -> Paid | I35: =IF(G35="","",DATEVALUE(G35)-DATEVALUE(C35)) -> 58 | J35: =IF(G35="",TODAY()-DATEVALUE(D35),DATEVALUE(G35)-DATEVALUE(D35)) -> 28 | K35: =IF(J35<=0,"Current",IF(J35<=30,"1-30 days",IF(J35<=60,"31-60 days",IF(J35<=90,"61-90 days","90+ days")))) -> 1-30 days
A36: INV-1034 | B36: Customer 013 | C36: 2026-01-11 | D36: 2026-02-10 | E36: 30 | F36: 5494 | G36: 2026-01-20 | H36: =IF(G36="","Open","Paid") -> Paid | I36: =IF(G36="","",DATEVALUE(G36)-DATEVALUE(C36)) -> 9 | J36: =IF(G36="",TODAY()-DATEVALUE(D36),DATEVALUE(G36)-DATEVALUE(D36)) -> -21 | K36: =IF(J36<=0,"Current",IF(J36<=30,"1-30 days",IF(J36<=60,"31-60 days",IF(J36<=90,"61-90 days","90+ days")))) -> Current
A37: INV-1035 | B37: Customer 059 | C37: 2026-04-23 | D37: 2026-05-23 | E37: 30 | F37: 2218.76 | G37: 2026-05-25 | H37: =IF(G37="","Open","Paid") -> Paid | I37: =IF(G37="","",DATEVALUE(G37)-DATEVALUE(C37)) -> 32 | J37: =IF(G37="",TODAY()-DATEVALUE(D37),DATEVALUE(G37)-DATEVALUE(D37)) -> 2 | K37: =IF(J37<=0,"Current",IF(J37<=30,"1-30 days",IF(J37<=60,"31-60 days",IF(J37<=90,"61-90 days","90+ days")))) -> 1-30 days
A38: INV-1036 | B38: Customer 011 | C38: 2026-05-14 | D38: 2026-07-13 | E38: 60 | F38: 2250.16 | G38: 2026-06-29 | H38: =IF(G38="","Open","Paid") -> Paid | I38: =IF(G38="","",DATEVALUE(G38)-DATEVALUE(C38)) -> 46 | J38: =IF(G38="",TODAY()-DATEVALUE(D38),DATEVALUE(G38)-DATEVALUE(D38)) -> -14 | K38: =IF(J38<=0,"Current",IF(J38<=30,"1-30 days",IF(J38<=60,"31-60 days",IF(J38<=90,"61-90 days","90+ days")))) -> Current
A39: INV-1037 | B39: Customer 028 | C39: 2026-01-08 | D39: 2026-02-07 | E39: 30 | F39: 9468.09 | G39: 2026-02-01 | H39: =IF(G39="","Open","Paid") -> Paid | I39: =IF(G39="","",DATEVALUE(G39)-DATEVALUE(C39)) -> 24 | J39: =IF(G39="",TODAY()-DATEVALUE(D39),DATEVALUE(G39)-DATEVALUE(D39)) -> -6 | K39: =IF(J39<=0,"Current",IF(J39<=30,"1-30 days",IF(J39<=60,"31-60 days",IF(J39<=90,"61-90 days","90+ days")))) -> Current
A40: INV-1038 | B40: Customer 019 | C40: 2026-04-09 | D40: 2026-05-24 | E40: 45 | F40: 2744.15 | G40: 2026-05-25 | H40: =IF(G40="","Open","Paid") -> Paid | I40: =IF(G40="","",DATEVALUE(G40)-DATEVALUE(C40)) -> 46 | J40: =IF(G40="",TODAY()-DATEVALUE(D40),DATEVALUE(G40)-DATEVALUE(D40)) -> 1 | K40: =IF(J40<=0,"Current",IF(J40<=30,"1-30 days",IF(J40<=60,"31-60 days",IF(J40<=90,"61-90 days","90+ days")))) -> 1-30 days
...

Sheet Aging Analysis
A1: Open AR — Aging Analysis
A3: Bucket | B3: Open Amount ($) | C3: % of Open AR
A4: Current | B4: =SUMIFS('Invoice Ledger'!F2:F421,'Invoice Ledger'!H2:H421,"Open",'Invoice Ledger'!K2:K421,A4) -> 153071.84 | C4: =B4/SUM($B$4:$B$8) -> 0.62924767
A5: 1-30 days | B5: =SUMIFS('Invoice Ledger'!F2:F421,'Invoice Ledger'!H2:H421,"Open",'Invoice Ledger'!K2:K421,A5) -> 57180.51 | C5: =B5/SUM($B$4:$B$8) -> 0.23505762
A6: 31-60 days | B6: =SUMIFS('Invoice Ledger'!F2:F421,'Invoice Ledger'!H2:H421,"Open",'Invoice Ledger'!K2:K421,A6) -> 17142.76 | C6: =B6/SUM($B$4:$B$8) -> 0.070470453
A7: 61-90 days | B7: =SUMIFS('Invoice Ledger'!F2:F421,'Invoice Ledger'!H2:H421,"Open",'Invoice Ledger'!K2:K421,A7) -> 15866.56 | C7: =B7/SUM($B$4:$B$8) -> 0.06522425
A8: 90+ days | B8: =SUMIFS('Invoice Ledger'!F2:F421,'Invoice Ledger'!H2:H421,"Open",'Invoice Ledger'!K2:K421,A8) -> 0 | C8: =B8/SUM($B$4:$B$8) -> 0
A9: Total Open AR | B9: =SUM(B4:B8) -> 243261.67
